Workbook

Sheet 8월
A1: 8월 | B1: 날짜 | C1: 08.04 | D1: 08.12 | E1: 08.18 | F1: 08.22 | G1: 08.23 | H1: 08.25 | I1: 08.26 | J1: 누적 점수
B2: 구분 | C2: 3차 정기모임 | D2: 4차 정기모임 | E2: 5차 정기모임 | F2: 비정기모임 | G2: 비정기모임 | H2: 비정기모임 | I2: 6차 정기모임 | L2: 보증금 환급 | M2: 기수 연장제한
B3: 활동 | C3: 이대 볼링 | D3: 강남 베이킹 | E3: 신촌 방탈출 | F3: 마곡나루 고기 | G3: 강남 술 | H3: 신촌 고기 | I3: 왕십리 개강파티 | L3: 대상자 여부 | M3: 대상자 여부
B4: 주최자 | C4: - | D4: - | E4: - | F4: 이진진 | G4: 이진진 | H4: 김지우 | I4: -
A5: 운영진 | B5: 이진진 | D5: 5 | E5: 3 | F5: 2 | G5: 2 | J5: =SUM(C5:I5)+'7월'!H5 -> 26 | L5: =IF(J5>=15,"O","X") -> O | M5: =IF(J5<=0,"O","X") -> X
B6: 이규엽 | C6: 3 | E6: 3 | I6: 3 | J6: =SUM(C6:I6)+'7월'!H6 -> 23 | L6: =IF(J6>=15,"O","X") -> O | M6: =IF(J6<=0,"O","X") -> X
B7: 윤민식 | C7: 3 | D7: 1 | E7: 3 | H7: 1 | I7: 3 | J7: =SUM(C7:I7)+'7월'!H7 -> 24 | L7: =IF(J7>=15,"O","X") -> O | M7: =IF(J7<=0,"O","X") -> X
B8: 신혜원 | C8: 1 | D8: 5 | I8: 3 | J8: =SUM(C8:I8)+'7월'!H8 -> 21 | L8: =IF(J8>=15,"O","X") -> O | M8: =IF(J8<=0,"O","X") -> X
B9: 김세미 | C9: 1 | I9: 3 | J9: =SUM(C9:I9)+'7월'!H9 -> 15 | L9: =IF(J9>=15,"O","X") -> O | M9: =IF(J9<=0,"O","X") -> X
A10: 활동회원 | B10: 임정연 | D10: 1 | G10: 1 | I10: 3 | J10: =SUM(C10:I10)+'7월'!H10 -> 7 | L10: =IF(J10>=15,"O","X") -> X | M10: =IF(J10<=0,"O","X") -> X
B11: 황인우 | C11: 1 | I11: 3 | J11: =SUM(C11:I11)+'7월'!H11 -> 4 | L11: =IF(J11>=15,"O","X") -> X | M11: =IF(J11<=0,"O","X") -> X
B12: 박서현 | D12: 1 | G12: 1 | I12: 3 | J12: =SUM(C12:I12)+'7월'!H12 -> 7 | L12: =IF(J12>=15,"O","X") -> X | M12: =IF(J12<=0,"O","X") -> X
B13: 김해찬 | E13: 1 | J13: =SUM(C13:I13)+'7월'!H13 -> 1 | L13: =IF(J13>=15,"O","X") -> X | M13: =IF(J13<=0,"O","X") -> X
B14: 이원준 | C14: 1 | I14: 3 | J14: =SUM(C14:I14)+'7월'!H14 -> 13 | L14: =IF(J14>=15,"O","X") -> X | M14: =IF(J14<=0,"O","X") -> X
B15: 하은희 | I15: 3 | J15: =SUM(C15:I15)+'7월'!H15 -> 3 | L15: =IF(J15>=15,"O","X") -> X | M15: =IF(J15<=0,"O","X") -> X
B16: 김민구 | D16: 5 | F16: 1 | J16: =SUM(C16:I16)+'7월'!H16 -> 6 | L16: =IF(J16>=15,"O","X") -> X | M16: =IF(J16<=0,"O","X") -> X
B17: 이광민 | C17: 1 | G17: 1 | I17: 3 | J17: =SUM(C17:I17)+'7월'!H17 -> 16 | L17: =IF(J17>=15,"O","X") -> O | M17: =IF(J17<=0,"O","X") -> X
B18: 김주곤 | C18: 3 | I18: 3 | J18: =SUM(C18:I18)+'7월'!H18 -> 17 | L18: =IF(J18>=15,"O","X") -> O | M18: =IF(J18<=0,"O","X") -> X
B19: 김태형 | C19: 1 | I19: 3 | J19: =SUM(C19:I19)+'7월'!H19 -> 12 | L19: =IF(J19>=15,"O","X") -> X | M19: =IF(J19<=0,"O","X") -> X
B20: 이성현 | J20: =SUM(C20:I20)+'7월'!H20 -> 6 | L20: =IF(J20>=15,"O","X") -> X | M20: =IF(J20<=0,"O","X") -> X
B21: 이수민 | D21: 1 | E21: 1 | G21: 1 | I21: 3 | J21: =SUM(C21:I21)+'7월'!H21 -> 13 | L21: =IF(J21>=15,"O","X") -> X | M21: =IF(J21<=0,"O","X") -> X
B22: 이주희 | J22: =SUM(C22:I22)+'7월'!H22 -> 5 | L22: =IF(J22>=15,"O","X") -> X | M22: =IF(J22<=0,"O","X") -> X
B23: 최지훈 | J23: =SUM(C23:I23)+'7월'!H23 -> 9 | L23: =IF(J23>=15,"O","X") -> X | M23: =IF(J23<=0,"O","X") -> X
B24: 권제인 | J24: =SUM(C24:I24)+'7월'!H24 -> 0 | L24: =IF(J24>=15,"O","X") -> X | M24: =IF(J24<=0,"O","X") -> O
B25: 김보라 | C25: 1 | J25: =SUM(C25:I25)+'7월'!H25 -> 1 | L25: =IF(J25>=15,"O","X") -> X | M25: =IF(J25<=0,"O","X") -> X
B26: 김지우 | H26: 2 | J26: =SUM(C26:I26)+'7월'!H26 -> 2 | L26: =IF(J26>=15,"O","X") -> X | M26: =IF(J26<=0,"O","X") -> X
B27: 박도연 | J27: =SUM(C27:I27)+'7월'!H27 -> 0 | L27: =IF(J27>=15,"O","X") -> X | M27: =IF(J27<=0,"O","X") -> O
B28: 오재민 | J28: =SUM(C28:I28)+'7월'!H28 -> 0 | L28: =IF(J28>=15,"O","X") -> X | M28: =IF(J28<=0,"O","X") -> O
B29: 이다영 | J29: =SUM(C29:I29)+'7월'!H29 -> 0 | L29: =IF(J29>=15,"O","X") -> X | M29: =IF(J29<=0,"O","X") -> O
B30: 이지원 | I30: 3 | J30: =SUM(C30:I30)+'7월'!H30 -> 3 | L30: =IF(J30>=15,"O","X") -> X | M30: =IF(J30<=0,"O","X") -> X
B31: 정하영 | J31: =SUM(C31:I31)+'7월'!H31 -> 0 | L31: =IF(J31>=15,"O","X") -> X | M31: =IF(J31<=0,"O","X") -> O
B32: 강준 | C32: 3 | I32: 3 | J32: =SUM(C32:I32)+'7월'!H32 -> 20 | L32: =IF(J32>=15,"O","X") -> O | M32: =IF(J32<=0,"O","X") -> X
B33: 김민지 | J33: =SUM(C33:I33)+'7월'!H33 -> 8 | L33: =IF(J33>=15,"O","X") -> X | M33: =IF(J33<=0,"O","X") -> X
B34: 김채린 | J34: =SUM(C34:I34)+'7월'!H34 -> 6 | L34: =IF(J34>=15,"O","X") -> X | M34: =IF(J34<=0,"O","X") -> X
B35: 박소현 | D35: 5 | F35: 1 | H35: 1 | J35: =SUM(C35:I35)+'7월'!H35 -> 19 | L35: =IF(J35>=15,"O","X") -> O | M35: =IF(J35<=0,"O","X") -> X
B36: 양진석 | D36: 5 | J36: =SUM(C36:I36)+'7월'!H36 -> 13 | L36: =IF(J36>=15,"O","X") -> X | M36: =IF(J36<=0,"O","X") -> X
B37: 이예림 | C37: 1 | G37: 1 | J37: =SUM(C37:I37)+'7월'!H37 -> 9 | L37: =IF(J37>=15,"O","X") -> X | M37: =IF(J37<=0,"O","X") -> X
B38: 이종헌 | J38: =SUM(C38:I38)+'7월'!H38 -> 8 | L38: =IF(J38>=15,"O","X") -> X | M38: =IF(J38<=0,"O","X") -> X
B39: 조용근 | C39: 1 | G39: 1 | I39: 3 | J39: =SUM(C39:I39)+'7월'!H39 -> 15 | L39: =IF(J39>=15,"O","X") -> O | M39: =IF(J39<=0,"O","X") -> X
B40: 조은서 | J40: =SUM(C40:I40)+'7월'!H40 -> 5 | L40: =IF(J40>=15,"O","X") -> X | M40: =IF(J40<=0,"O","X") -> X
...

Sheet 7월
A1: 7월 | B1: 날짜 | C1: 07.08 | D1: 07.14 | E1: 07.18 | F1: 07.22 | G1: 07.29 | H1: 누적 점수
B2: 구분 | C2: 오리엔테이션 | D2: 1차 정기모임 | E2: 비정기모임 | F2: 2차 정기모임 | G2: 여름 엠티
B3: 활동 | C3: - | D3: 서울대 보드게임 | E3: 합정 술 | F3: 대학로 연극 | G3: 수상 레저
B4: 주최자 | C4: - | D4: - | E4: 이규엽 | G4: -
A5: 운영진 | B5: 이진진 | C5: 5 | D5: 3 | E5: 1 | G5: 5 | H5: =SUM(C5:G5) -> 14
B6: 이규엽 | C6: 5 | D6: 1 | E6: 2 | F6: 1 | G6: 5 | H6: =SUM(C6:G6) -> 14
B7: 윤민식 | C7: 5 | D7: 1 | E7: 1 | F7: 1 | G7: 5 | H7: =SUM(C7:G7) -> 13
B8: 신혜원 | C8: 5 | D8: 1 | E8: 1 | G8: 5 | H8: =SUM(C8:G8) -> 12
B9: 김세미 | C9: 5 | E9: 1 | G9: 5 | H9: =SUM(C9:G9) -> 11
A10: 활동회원 | B10: 임정연 | D10: 1 | F10: 1 | H10: =SUM(C10:G10) -> 2
B11: 황인우 | H11: =SUM(C11:G11) -> 0
B12: 박서현 | D12: 1 | F12: 1 | H12: =SUM(C12:G12) -> 2
B13: 김해찬 | H13: =SUM(C13:G13) -> 0
B14: 이원준 | C14: 5 | D14: 3 | F14: 1 | H14: =SUM(C14:G14) -> 9
B15: 하은희 | H15: =SUM(C15:G15) -> 0
B16: 김민구 | H16: =SUM(C16:G16) -> 0
B17: 이광민 | C17: 5 | F17: 1 | G17: 5 | H17: =SUM(C17:G17) -> 11
B18: 김주곤 | C18: 5 | F18: 1 | G18: 5 | H18: =SUM(C18:G18) -> 11
B19: 김태형 | C19: 5 | D19: 3 | H19: =SUM(C19:G19) -> 8
B20: 이성현 | D20: 1 | G20: 5 | H20: =SUM(C20:G20) -> 6
B21: 이수민 | C21: 5 | D21: 1 | F21: 1 | H21: =SUM(C21:G21) -> 7
B22: 이주희 | G22: 5 | H22: =SUM(C22:G22) -> 5
B23: 최지훈 | C23: 5 | D23: 3 | E23: 1 | H23: =SUM(C23:G23) -> 9
B24: 권제인 | H24: =SUM(C24:G24) -> 0
B25: 김보라 | H25: =SUM(C25:G25) -> 0
B26: 김지우 | H26: =SUM(C26:G26) -> 0
B27: 박도연 | H27: =SUM(C27:G27) -> 0
B28: 오재민 | H28: =SUM(C28:G28) -> 0
B29: 이다영 | H29: =SUM(C29:G29) -> 0
B30: 이지원 | H30: =SUM(C30:G30) -> 0
B31: 정하영 | H31: =SUM(C31:G31) -> 0
B32: 강준 | C32: 5 | D32: 3 | E32: 1 | G32: 5 | H32: =SUM(C32:G32) -> 14
B33: 김민지 | C33: 5 | D33: 3 | H33: =SUM(C33:G33) -> 8
B34: 김채린 | C34: 5 | F34: 1 | H34: =SUM(C34:G34) -> 6
B35: 박소현 | C35: 5 | E35: 1 | F35: 1 | G35: 5 | H35: =SUM(C35:G35) -> 12
B36: 양진석 | C36: 5 | D36: 3 | H36: =SUM(C36:G36) -> 8
B37: 이예림 | C37: 5 | D37: 1 | F37: 1 | H37: =SUM(C37:G37) -> 7
B38: 이종헌 | C38: 5 | D38: 3 | H38: =SUM(C38:G38) -> 8
B39: 조용근 | C39: 5 | G39: 5 | H39: =SUM(C39:G39) -> 10
B40: 조은서 | C40: 5 | H40: =SUM(C40:G40) -> 5
...
