Workbook

Sheet 5월
A1: 5월 | B1: 날짜 | C1: 05.02 | D1: 05.06 | E1: 05.09 | F1: 05.19 | G1: 05.25 | H1: 05.27 | I1: 05.31 | J1: 누적 점수
B2: 구분 | C2: 비정기모임 | D2: 엠티 | E2: 비정기모임 | F2: 5차 정기모임 | G2: 비정기모임 | H2: 6차 정기모임 | I2: 비정기모임
B3: 활동 | C3: 한양대 연주회 | D3: - | E3: 건대 술 | F3: 신림 클라이밍 | H3: 강남 전시회 | I3: 을지로 술
B4: 주최자 | C4: 이진진 | D4: - | E4: 박서현 | F4: - | G4: 임정연 | H4: - | I4: 이규엽
A5: 운영진 | B5: 이진진 | C5: 2 | D5: 5 | E5: 1 | F5: 3 | H5: 3 | I5: 1 | J5: =SUM(C5:I5)+'4월'!K5 -> 35
B6: 백다은 | J6: =SUM(C6:I6)+'4월'!K6 -> 6
B7: 홍석범 | F7: 3 | J7: =SUM(C7:I7)+'4월'!K7 -> 16
B8: 이규엽 | D8: 5 | E8: 1 | I8: 2 | J8: =SUM(C8:I8)+'4월'!K8 -> 22
B9: 윤민식 | D9: 5 | E9: 1 | I9: 1 | J9: =SUM(C9:I9)+'4월'!K9 -> 23
A10: 활동회원 | B10: 임정연 | G10: 2 | I10: 1 | J10: =SUM(C10:I10)+'4월'!K10 -> 11
B11: 황인우 | D11: 5 | J11: =SUM(C11:I11)+'4월'!K11 -> 11
B12: 김승현 | J12: =SUM(C12:I12)+'4월'!K12 -> 9
B13: 박서현 | E13: 2 | G13: 1 | I13: 1 | J13: =SUM(C13:I13)+'4월'!K13 -> 15
B14: 김해찬 | J14: =SUM(C14:I14)+'4월'!K14 -> 4
B15: 이원준 | J15: =SUM(C15:I15)+'4월'!K15 -> 7
B16: 오승주 | J16: =SUM(C16:I16)+'4월'!K16 -> 0
B17: 하은희 | D17: 5 | J17: =SUM(C17:I17)+'4월'!K17 -> 5
B18: 고재준 | J18: =SUM(C18:I18)+'4월'!K18 -> 1
B19: 김지윤 | J19: =SUM(C19:I19)+'4월'!K19 -> 5
B20: 김주곤 | D20: 5 | J20: =SUM(C20:I20)+'4월'!K20 -> 8
B21: 김태형 | J21: =SUM(C21:I21)+'4월'!K21 -> 0
B22: 이성현 | C22: 1 | D22: 5 | E22: 1 | G22: 1 | J22: =SUM(C22:I22)+'4월'!K22 -> 16
B23: 이수민 | C23: 1 | D23: 5 | J23: =SUM(C23:I23)+'4월'!K23 -> 14
B24: 이주희 | H24: 3 | J24: =SUM(C24:I24)+'4월'!K24 -> 8
B25: 최지훈 | D25: 5 | H25: 3 | J25: =SUM(C25:I25)+'4월'!K25 -> 17
B26: 권제인 | J26: =SUM(C26:I26)+'4월'!K26 -> 10
B27: 김보라 | D27: 5 | J27: =SUM(C27:I27)+'4월'!K27 -> 12
B28: 김세미 | E28: 1 | J28: =SUM(C28:I28)+'4월'!K28 -> 12
B29: 김준용 | J29: =SUM(C29:I29)+'4월'!K29 -> 1
B30: 김지우 | F30: 1 | J30: =SUM(C30:I30)+'4월'!K30 -> 5
B31: 명수민 | J31: =SUM(C31:I31)+'4월'!K31 -> 5
B32: 박가연 | E32: 1 | J32: =SUM(C32:I32)+'4월'!K32 -> 19
B33: 박도연 | J33: =SUM(C33:I33)+'4월'!K33 -> 1
B34: 서보성 | J34: =SUM(C34:I34)+'4월'!K34 -> 6
B35: 신혜원 | C35: 1 | J35: =SUM(C35:I35)+'4월'!K35 -> 6
B36: 양진영 | J36: =SUM(C36:I36)+'4월'!K36 -> 1
B37: 오재민 | E37: 1 | J37: =SUM(C37:I37)+'4월'!K37 -> 10
B38: 이다영 | J38: =SUM(C38:I38)+'4월'!K38 -> 0
B39: 이유곤 | J39: =SUM(C39:I39)+'4월'!K39 -> 5
B40: 이지원 | D40: 5 | F40: 1 | J40: =SUM(C40:I40)+'4월'!K40 -> 6
...

Sheet 4월
A1: 4월 | B1: 날짜 | C1: 04.04 | D1: 04.08 | E1: 04.14 | F1: 04.18 | G1: 04.21 | H1: 04.22 | I1: 04.25 | J1: 04.29 | K1: 누적 점수
B2: 구분 | C2: 비정기모임 | D2: 2차 정기모임 | E2: 3차 정기모임 | F2: 비정기모임 | G2: 비정기모임 | H2: 4차 정기모임 | I2: 비정기모임 | J2: 비정기모임
B3: 활동 | C3: 신촌 술 | D3: 한강 나들이 | E3: 건대 영화 | F3: 신촌 카공 | G3: 방배 술 | H3: 종각 볼링 | I3: 홍대 술 | J3: 서울대입구 술
B4: 주최자 | C4: 홍석범 | D4: - | E4: - | F4: 윤민식 | G4: 이진진 | H4: - | I4: 이규엽, 윤민식 | J4: 이진진
A5: 운영진 | B5: 이진진 | C5: 1 | E5: 3 | F5: 1 | G5: 2 | H5: 3 | I5: 1 | J5: 2 | K5: =SUM(C5:J5)+'3월'!F5 -> 20
B6: 백다은 | C6: 1 | K6: =SUM(C6:J6)+'3월'!F6 -> 6
B7: 홍석범 | C7: 2 | D7: 3 | H7: 3 | K7: =SUM(C7:J7)+'3월'!F7 -> 13
B8: 이규엽 | C8: 1 | D8: 1 | F8: 1 | H8: 1 | I8: 2 | K8: =SUM(C8:J8)+'3월'!F8 -> 14
B9: 윤민식 | C9: 1 | D9: 1 | E9: 1 | F9: 2 | G9: 1 | H9: 1 | I9: 2 | K9: =SUM(C9:J9)+'3월'!F9 -> 16
A10: 활동회원 | B10: 임정연 | C10: 1 | E10: 3 | G10: 1 | H10: 3 | K10: =SUM(C10:J10)+'3월'!F10 -> 8
B11: 황인우 | D11: 1 | K11: =SUM(C11:J11)+'3월'!F11 -> 6
B12: 김승현 | K12: =SUM(C12:J12)+'3월'!F12 -> 9
B13: 박서현 | C13: 1 | E13: 1 | G13: 1 | H13: 3 | K13: =SUM(C13:J13)+'3월'!F13 -> 11
B14: 김해찬 | C14: 1 | H14: 1 | K14: =SUM(C14:J14)+'3월'!F14 -> 4
B15: 이원준 | D15: 1 | K15: =SUM(C15:J15)+'3월'!F15 -> 7
B16: 오승주 | K16: =SUM(C16:J16)+'3월'!F16 -> 0
B17: 하은희 | K17: =SUM(C17:J17)+'3월'!F17 -> 0
B18: 고재준 | K18: =SUM(C18:J18)+'3월'!F18 -> 1
B19: 김지윤 | K19: =SUM(C19:J19)+'3월'!F19 -> 5
B20: 김주곤 | E20: 3 | K20: =SUM(C20:J20)+'3월'!F20 -> 3
B21: 김태형 | K21: =SUM(C21:J21)+'3월'!F21 -> 0
B22: 이성현 | C22: 1 | G22: 1 | I22: 1 | K22: =SUM(C22:J22)+'3월'!F22 -> 8
B23: 이수민 | C23: 1 | H23: 3 | K23: =SUM(C23:J23)+'3월'!F23 -> 8
B24: 이주희 | K24: =SUM(C24:J24)+'3월'!F24 -> 5
B25: 최지훈 | C25: 1 | D25: 3 | F25: 1 | G25: 1 | I25: 1 | J25: 1 | K25: =SUM(C25:J25)+'3월'!F25 -> 9
B26: 권제인 | C26: 1 | D26: 1 | F26: 1 | I26: 1 | K26: =SUM(C26:J26)+'3월'!F26 -> 10
B27: 김보라 | D27: 1 | I27: 1 | K27: =SUM(C27:J27)+'3월'!F27 -> 7
B28: 김세미 | C28: 1 | D28: 3 | E28: 1 | I28: 1 | K28: =SUM(C28:J28)+'3월'!F28 -> 11
B29: 김준용 | E29: 1 | K29: =SUM(C29:J29)+'3월'!F29 -> 1
B30: 김지우 | E30: 3 | I30: 1 | K30: =SUM(C30:J30)+'3월'!F30 -> 4
B31: 명수민 | K31: =SUM(C31:J31)+'3월'!F31 -> 5
B32: 박가연 | D32: 3 | E32: 3 | G32: 1 | H32: 3 | K32: =SUM(C32:J32)+'3월'!F32 -> 18
B33: 박도연 | K33: =SUM(C33:J33)+'3월'!F33 -> 1
B34: 서보성 | D34: 1 | K34: =SUM(C34:J34)+'3월'!F34 -> 6
B35: 신혜원 | K35: =SUM(C35:J35)+'3월'!F35 -> 5
B36: 양진영 | C36: 1 | K36: =SUM(C36:J36)+'3월'!F36 -> 1
B37: 오재민 | G37: 1 | K37: =SUM(C37:J37)+'3월'!F37 -> 9
B38: 이다영 | K38: =SUM(C38:J38)+'3월'!F38 -> 0
B39: 이유곤 | K39: =SUM(C39:J39)+'3월'!F39 -> 5
B40: 이지원 | K40: =SUM(C40:J40)+'3월'!F40 -> 0
...

Sheet 3월
A1: 3월 | B1: 날짜 | C1: 03.24 | D1: 03.28 | E1: 03.31 | F1: 누적 점수
B2: 구분 | C2: 오리엔테이션 | D2: 비정기모임 | E2: 1차 정기모임
B3: 활동 | C3: - | D3: 신촌 술 | E3: 왕십리 보드게임
B4: 주최자 | C4: - | D4: 이규엽 | E4: -
A5: 운영진 | B5: 이진진 | C5: 5 | D5: 1 | E5: 1 | F5: =SUM(C5:E5) -> 7
B6: 백다은 | C6: 5 | F6: =SUM(C6:E6) -> 5
B7: 홍석범 | C7: 5 | F7: =SUM(C7:E7) -> 5
B8: 이규엽 | C8: 5 | D8: 2 | E8: 1 | F8: =SUM(C8:E8) -> 8
B9: 윤민식 | C9: 5 | D9: 1 | E9: 1 | F9: =SUM(C9:E9) -> 7
A10: 활동회원 | B10: 임정연 | F10: =SUM(C10:E10) -> 0
B11: 황인우 | C11: 5 | F11: =SUM(C11:E11) -> 5
B12: 김승현 | C12: 5 | D12: 1 | E12: 3 | F12: =SUM(C12:E12) -> 9
B13: 박서현 | C13: 5 | F13: =SUM(C13:E13) -> 5
B14: 김해찬 | D14: 1 | E14: 1 | F14: =SUM(C14:E14) -> 2
B15: 이원준 | C15: 5 | E15: 1 | F15: =SUM(C15:E15) -> 6
B16: 오승주 | F16: =SUM(C16:E16) -> 0
B17: 하은희 | F17: =SUM(C17:E17) -> 0
B18: 고재준 | E18: 1 | F18: =SUM(C18:E18) -> 1
B19: 김지윤 | C19: 5 | F19: =SUM(C19:E19) -> 5
B20: 김주곤 | F20: =SUM(C20:E20) -> 0
B21: 김태형 | F21: =SUM(C21:E21) -> 0
B22: 이성현 | C22: 5 | F22: =SUM(C22:E22) -> 5
B23: 이수민 | C23: 1 | E23: 3 | F23: =SUM(C23:E23) -> 4
B24: 이주희 | C24: 5 | F24: =SUM(C24:E24) -> 5
B25: 최지훈 | C25: 1 | F25: =SUM(C25:E25) -> 1
B26: 권제인 | C26: 5 | D26: 1 | F26: =SUM(C26:E26) -> 6
B27: 김보라 | C27: 5 | F27: =SUM(C27:E27) -> 5
B28: 김세미 | C28: 5 | F28: =SUM(C28:E28) -> 5
B29: 김준용 | F29: =SUM(C29:E29) -> 0
B30: 김지우 | F30: =SUM(C30:E30) -> 0
B31: 명수민 | C31: 5 | F31: =SUM(C31:E31) -> 5
B32: 박가연 | C32: 5 | E32: 3 | F32: =SUM(C32:E32) -> 8
B33: 박도연 | C33: 1 | F33: =SUM(C33:E33) -> 1
B34: 서보성 | C34: 5 | F34: =SUM(C34:E34) -> 5
B35: 신혜원 | C35: 5 | F35: =SUM(C35:E35) -> 5
B36: 양진영 | F36: =SUM(C36:E36) -> 0
B37: 오재민 | C37: 5 | E37: 3 | F37: =SUM(C37:E37) -> 8
B38: 이다영 | F38: =SUM(C38:E38) -> 0
B39: 이유곤 | C39: 5 | F39: =SUM(C39:E39) -> 5
B40: 이지원 | F40: =SUM(C40:E40) -> 0
...
