Workbook

Sheet 11월
A1: 11월 | B1: 날짜 | C1: 11.01 | D1: 11.04 | E1: 11.11 | F1: 11.12 | G1: 11.15 | H1: 11.17 | I1: 11.18 | J1: 11.19 | K1: 11.24 | L1: 11.28 | M1: 11.29 | N1: 누적 점수
B2: 구분 | C2: 비정기모임 | D2: 비정기모임 | E2: 8차 정기모임 | F2: 비정기모임 | G2: 비정기모임 | H2: 9차 정기모임 | I2: 비정기모임 | J2: 비정기모임 | K2: 비정기모임 | L2: 비정기모임 | M2: 비정기모임
B3: 활동 | C3: 신림 술 | D3: 홍대 술 | E3: 신논현 빼빼로 | F3: 안암 술 | G3: 홍대 술 | H3: 강남 볼링 | I3: 홍대 술 | J3: 왕십리 곱창 | K3: 왕십리 술 | L3: 합정 술 | M3: 서울대입구 술
B4: 주최자 | C4: 이원준 | D4: 이주연 | E4: - | F4: 홍채원 | G4: 윤민식 | H4: - | I4: 홍석범 | J4: 임정연 | K4: 박한웅 | L4: 이규엽 | M4: 이원준
A5: 운영진 | B5: 이진진 | C5: 1 | D5: 1 | F5: 1 | G5: 1 | H5: 3 | I5: 1 | K5: 1 | M5: 1 | N5: =SUM(C5:M5)+'10월'!I5 -> 44
B6: 이규엽 | D6: 1 | G6: 1 | L6: 2 | N6: =SUM(C6:M6)+'10월'!I6 -> 25
B7: 오소현 | N7: =SUM(C7:M7)+'10월'!I7 -> 8
B8: 윤민식 | C8: 1 | G8: 2 | N8: =SUM(C8:M8)+'10월'!I8 -> 23
B9: 신혜원 | C9: 1 | N9: =SUM(C9:M9)+'10월'!I9 -> 7
B10: 김세미 | D10: 1 | N10: =SUM(C10:M10)+'10월'!I10 -> 14
B11: 이원준 | C11: 2 | E11: 5 | G11: 1 | M11: 2 | N11: =SUM(C11:M11)+'10월'!I16 -> 23
B12: 박소현 | N12: =SUM(C12:M12)+'10월'!I29 -> 20
B13: 이예림 | C13: 1 | E13: 5 | K13: 1 | N13: =SUM(C13:M13)+'10월'!I31 -> 15
B14: 권희원 | N14: =SUM(C14:M14)+'10월'!I35 -> 13
B15: 신희찬 | C15: 1 | D15: 1 | G15: 1 | H15: 3 | N15: =SUM(C15:M15)+'10월'!I44 -> 38
A16: 활동회원 | B16: 임정연 | H16: 1 | J16: 2 | L16: 1 | N16: =SUM(C16:M16)+'10월'!I11 -> 7
B17: 홍석범 | E17: 5 | I17: 2 | N17: =SUM(C17:M17)+'10월'!I12 -> 15
B18: 황인우 | H18: 1 | K18: 1 | N18: =SUM(C18:M18)+'10월'!I13 -> 3
B19: 박서현 | H19: 1 | L19: 1 | N19: =SUM(C19:M19)+'10월'!I14 -> 6
B20: 김해찬 | N20: =SUM(C20:M20)+'10월'!I15 -> 9
B21: 김민구 | D21: 1 | J21: 1 | N21: =SUM(C21:M21)+'10월'!I17 -> 8
B22: 이광민 | C22: 1 | J22: 1 | N22: =SUM(C22:M22)+'10월'!I18 -> 12
B23: 김주곤 | N23: =SUM(C23:M23)+'10월'!I19 -> 0
B24: 김태형 | N24: =SUM(C24:M24)+'10월'!I20 -> 0
B25: 이수민 | M25: 1 | N25: =SUM(C25:M25)+'10월'!I21 -> 15
B26: 류혜원 | N26: =SUM(C26:M26)+'10월'!I22 -> 0
B27: 김보라 | N27: =SUM(C27:M27)+'10월'!I23 -> 8
B28: 김지우 | N28: =SUM(C28:M28)+'10월'!I24 -> 8
B29: 오재민 | N29: =SUM(C29:M29)+'10월'!I25 -> 0
B30: 강준 | N30: =SUM(C30:M30)+'10월'!I26 -> 4
B31: 김민지 | N31: =SUM(C31:M31)+'10월'!I27 -> 0
B32: 김채린 | N32: =SUM(C32:M32)+'10월'!I28 -> 0
B33: 양진석 | N33: =SUM(C33:M33)+'10월'!I30 -> 0
B34: 조용근 | J34: 1 | N34: =SUM(C34:M34)+'10월'!I32 -> 9
B35: 홍채원 | E35: 1 | F35: 2 | N35: =SUM(C35:M35)+'10월'!I33 -> 17
B36: 권지연 | C36: 1 | D36: 1 | E36: 5 | H36: 1 | J36: 1 | K36: 1 | N36: =SUM(C36:M36)+'10월'!I34 -> 23
B37: 김용현 | N37: =SUM(C37:M37)+'10월'!I36 -> 8
B38: 문제원 | C38: 1 | D38: 1 | E38: 5 | K38: 1 | M38: 1 | N38: =SUM(C38:M38)+'10월'!I37 -> 28
B39: 민현호 | N39: =SUM(C39:M39)+'10월'!I38 -> 6
B40: 박한웅 | F40: 1 | H40: 3 | K40: 2 | N40: =SUM(C40:M40)+'10월'!I39 -> 14
...

Sheet 10월
A1: 10월 | B1: 날짜 | C1: 10.01 | D1: 10.07 | E1: 10.20 | F1: 10.25 | G1: 10.28 | H1: 10.29 | I1: 누적 점수
B2: 구분 | C2: 비정기모임 | D2: 5차 정기모임 | E2: 6차 정기모임 | F2: 비정기모임 | G2: 7차 정기모임 | H2: 비정기모임
B3: 활동 | C3: 신촌 술 | D3: 노들 불꽃놀이 | E3: 신촌 고기집 | F3: 신촌 술 | G3: 요리대회 | H3: 신촌 술
B4: 주최자 | C4: 윤민식 | D4: - | E4: - | F4: 이규엽 | G4: - | H4: 이지원
A5: 운영진 | B5: 이진진 | D5: 3 | E5: 3 | F5: 1 | G5: 5 | H5: 1 | I5: =SUM(C5:H5)+'9월'!M5 -> 34
B6: 이규엽 | C6: 1 | F6: 2 | G6: 5 | I6: =SUM(C6:H6)+'9월'!M6 -> 21
B7: 오소현 | I7: =SUM(C7:H7)+'9월'!M7 -> 8
B8: 윤민식 | C8: 2 | G8: 5 | I8: =SUM(C8:H8)+'9월'!M8 -> 20
B9: 신혜원 | C9: 1 | I9: =SUM(C9:H9)+'9월'!M9 -> 6
B10: 김세미 | G10: 5 | I10: =SUM(C10:H10)+'9월'!M10 -> 13
A11: 활동회원 | B11: 임정연 | C11: 1 | I11: =SUM(C11:H11)+'9월'!M11 -> 3
B12: 홍석범 | G12: 5 | I12: =SUM(C12:H12)+'9월'!M12 -> 8
B13: 황인우 | D13: 1 | I13: =SUM(C13:H13)+'9월'!M13 -> 1
B14: 박서현 | C14: 1 | H14: 1 | I14: =SUM(C14:H14)+'9월'!M14 -> 4
B15: 김해찬 | G15: 5 | I15: =SUM(C15:H15)+'9월'!M15 -> 9
B16: 이원준 | D16: 1 | H16: 1 | I16: =SUM(C16:H16)+'9월'!M16 -> 13
B17: 김민구 | G17: 5 | I17: =SUM(C17:H17)+'9월'!M17 -> 6
B18: 이광민 | C18: 1 | G18: 5 | I18: =SUM(C18:H18)+'9월'!M18 -> 10
B19: 김주곤 | I19: =SUM(C19:H19)+'9월'!M19 -> 0
B20: 김태형 | I20: =SUM(C20:H20)+'9월'!M20 -> 0
B21: 이수민 | G21: 5 | I21: =SUM(C21:H21)+'9월'!M21 -> 14
B22: 류혜원 | I22: =SUM(C22:H22)+'9월'!M22 -> 0
B23: 김보라 | G23: 5 | I23: =SUM(C23:H23)+'9월'!M23 -> 8
B24: 김지우 | D24: 3 | I24: =SUM(C24:H24)+'9월'!M24 -> 8
B25: 오재민 | I25: =SUM(C25:H25)+'9월'!M25 -> 0
B26: 강준 | C26: 1 | I26: =SUM(C26:H26)+'9월'!M26 -> 4
B27: 김민지 | I27: =SUM(C27:H27)+'9월'!M27 -> 0
B28: 김채린 | I28: =SUM(C28:H28)+'9월'!M28 -> 0
B29: 박소현 | D29: 3 | G29: 5 | I29: =SUM(C29:H29)+'9월'!M29 -> 20
B30: 양진석 | I30: =SUM(C30:H30)+'9월'!M30 -> 0
B31: 이예림 | C31: 1 | H31: 1 | I31: =SUM(C31:H31)+'9월'!M31 -> 8
B32: 조용근 | G32: 5 | I32: =SUM(C32:H32)+'9월'!M32 -> 8
B33: 홍채원 | D33: 1 | H33: 1 | I33: =SUM(C33:H33)+'9월'!M33 -> 14
B34: 권지연 | C34: 1 | G34: 5 | I34: =SUM(C34:H34)+'9월'!M34 -> 13
B35: 권희원 | C35: 1 | G35: 5 | I35: =SUM(C35:H35)+'9월'!M35 -> 13
B36: 김용현 | I36: =SUM(C36:H36)+'9월'!M36 -> 8
B37: 문제원 | C37: 1 | G37: 5 | H37: 1 | I37: =SUM(C37:H37)+'9월'!M37 -> 19
B38: 민현호 | I38: =SUM(C38:H38)+'9월'!M38 -> 6
B39: 박한웅 | G39: 5 | I39: =SUM(C39:H39)+'9월'!M39 -> 8
B40: 배규현 | C40: 1 | I40: =SUM(C40:H40)+'9월'!M40 -> 7
...

Sheet 9월
A1: 9월 | B1: 날짜 | C1: 09.02 | D1: 09.08 | E1: 09.09 | F1: 09.15 | G1: 09.16 | H1: 09.22 | I1: 09.23 | J1: 09.27 | K1: 09.28 | L1: 09.30 | M1: 누적 점수
B2: 구분 | C2: 오리엔테이션 | D2: 비정기모임 | E2: 1차 정기모임 | F2: 2차 정기모임 | G2: 비정기모임 | H2: 비정기모임 | I2: 3차 정기모임 | J2: 비정기모임 | K2: 비정기모임 | L2: 4차 정기모임
B3: 활동 | C3: - | D3: 교대 자전거 | E3: 종로 광장시장 | F3: 대학로 연극 | G3: 건대 술 | H3: 신촌 술 | I3: 여의도 한강 | J3: 홍대 술 | K3: 홍대 술 | L3: 캐리비안베이
B4: 주최자 | C4: - | D4: 이진진 | E4: - | F4: - | G4: 임정연, 박서현 | H4: 이진진 | I4: - | J4: 유지훈 | K4: 박소현 | L4: -
A5: 운영진 | B5: 이진진 | C5: 5 | D5: 2 | E5: 3 | F5: 1 | G5: 1 | H5: 2 | I5: 3 | K5: 1 | L5: 3 | M5: =SUM(C5:L5) -> 21
B6: 이규엽 | C6: 5 | E6: 3 | F6: 1 | I6: 3 | K6: 1 | M6: =SUM(C6:L6) -> 13
B7: 오소현 | C7: 5 | F7: 3 | M7: =SUM(C7:L7) -> 8
B8: 윤민식 | C8: 5 | E8: 3 | F8: 1 | G8: 1 | I8: 3 | M8: =SUM(C8:L8) -> 13
B9: 신혜원 | C9: 3 | I9: 1 | K9: 1 | M9: =SUM(C9:L9) -> 5
B10: 김세미 | C10: 5 | I10: 3 | M10: =SUM(C10:L10) -> 8
A11: 활동회원 | B11: 임정연 | G11: 2 | M11: =SUM(C11:L11) -> 2
B12: 홍석범 | I12: 3 | M12: =SUM(C12:L12) -> 3
B13: 황인우 | M13: =SUM(C13:L13) -> 0
B14: 박서현 | G14: 2 | M14: =SUM(C14:L14) -> 2
B15: 김해찬 | F15: 3 | G15: 1 | M15: =SUM(C15:L15) -> 4
B16: 이원준 | C16: 5 | E16: 3 | I16: 3 | M16: =SUM(C16:L16) -> 11
B17: 김민구 | F17: 1 | M17: =SUM(C17:L17) -> 1
B18: 이광민 | C18: 3 | E18: 1 | M18: =SUM(C18:L18) -> 4
B19: 김주곤 | M19: =SUM(C19:L19) -> 0
B20: 김태형 | M20: =SUM(C20:L20) -> 0
B21: 이수민 | C21: 3 | D21: 1 | E21: 1 | F21: 1 | L21: 3 | M21: =SUM(C21:L21) -> 9
B22: 류혜원 | M22: =SUM(C22:L22) -> 0
B23: 김보라 | E23: 3 | M23: =SUM(C23:L23) -> 3
B24: 김지우 | C24: 5 | M24: =SUM(C24:L24) -> 5
B25: 오재민 | M25: =SUM(C25:L25) -> 0
B26: 강준 | C26: 3 | M26: =SUM(C26:L26) -> 3
B27: 김민지 | M27: =SUM(C27:L27) -> 0
B28: 김채린 | M28: =SUM(C28:L28) -> 0
B29: 박소현 | C29: 3 | E29: 3 | J29: 1 | K29: 2 | L29: 3 | M29: =SUM(C29:L29) -> 12
B30: 양진석 | M30: =SUM(C30:L30) -> 0
B31: 이예림 | E31: 1 | G31: 1 | I31: 3 | J31: 1 | M31: =SUM(C31:L31) -> 6
B32: 조용근 | E32: 3 | M32: =SUM(C32:L32) -> 3
B33: 홍채원 | C33: 5 | D33: 1 | E33: 3 | F33: 1 | G33: 1 | H33: 1 | M33: =SUM(C33:L33) -> 12
B34: 권지연 | E34: 3 | I34: 3 | J34: 1 | M34: =SUM(C34:L34) -> 7
B35: 권희원 | C35: 5 | D35: 1 | E35: 1 | M35: =SUM(C35:L35) -> 7
B36: 김용현 | C36: 5 | F36: 3 | M36: =SUM(C36:L36) -> 8
B37: 문제원 | C37: 5 | E37: 3 | I37: 3 | J37: 1 | M37: =SUM(C37:L37) -> 12
B38: 민현호 | C38: 5 | D38: 1 | M38: =SUM(C38:L38) -> 6
B39: 박한웅 | E39: 3 | M39: =SUM(C39:L39) -> 3
B40: 배규현 | C40: 5 | D40: 1 | M40: =SUM(C40:L40) -> 6
...
