Workbook

Sheet 4월
A1: 4월 | B1: 날짜 | C1: 04.02 | D1: 04.06 | E1: 04.22 | F1: 누적 점수
B2: 구분 | C2: 비정기모임 | D2: 4차 정기모임 | E2: 비정기모임
B3: 활동 | C3: 신촌 | D3: 혜화 연극 | E3: 합정
B4: 주최자 | C4: 이원준, 이규엽 | D4: - | E4: 이규엽
A5: 운영진 | B5: 이원준 | C5: 2 | D5: 1 | F5: =SUM(C5:E5)+'3월'!J5 -> 16
B6: 이진진 | C6: 1 | D6: 3 | E6: 1 | F6: =SUM(C6:E6)+'3월'!J6 -> 20
B7: 이예림 | F7: =SUM(C7:E7)+'3월'!J7 -> 7
B8: 신희찬 | F8: =SUM(C8:E8)+'3월'!J8 -> 8
B9: 문제원 | F9: =SUM(C9:E9)+'3월'!J9 -> 11
B10: 유지훈 | F10: =SUM(C10:E10)+'3월'!J10 -> 15
B11: 이주연 | F11: =SUM(C11:E11)+'3월'!J11 -> 5
A12: 활동회원 | B12: 홍석범 | F12: =SUM(C12:E12)+'3월'!J12 -> 3
B13: 황인우 | D13: 1 | F13: =SUM(C13:E13)+'3월'!J13 -> 7
B14: 김해찬 | D14: 1 | F14: =SUM(C14:E14)+'3월'!J14 -> 6
B15: 이규엽 | C15: 2 | E15: 2 | F15: =SUM(C15:E15)+'3월'!J15 -> 12
B16: 하은희 | F16: =SUM(C16:E16)+'3월'!J16 -> 3
B17: 윤민식 | F17: =SUM(C17:E17)+'3월'!J17 -> 6
B18: 이광민 | F18: =SUM(C18:E18)+'3월'!J18 -> 8
B19: 이성현 | F19: =SUM(C19:E19)+'3월'!J19 -> 5
B20: 이수민 | F20: =SUM(C20:E20)+'3월'!J20 -> 7
B21: 이지원 | F21: =SUM(C21:E21)+'3월'!J21 -> 3
B22: 박소현 | E22: 1 | F22: =SUM(C22:E22)+'3월'!J22 -> 4
B23: 양진석 | F23: =SUM(C23:E23)+'3월'!J23 -> 0
B24: 홍채원 | F24: =SUM(C24:E24)+'3월'!J24 -> 8
B25: 권지연 | F25: =SUM(C25:E25)+'3월'!J25 -> 8
B26: 권희원 | F26: =SUM(C26:E26)+'3월'!J26 -> 0
B27: 배규현 | F27: =SUM(C27:E27)+'3월'!J27 -> 0
B28: 배환규 | D28: 3 | F28: =SUM(C28:E28)+'3월'!J28 -> 14
B29: 안우석 | F29: =SUM(C29:E29)+'3월'!J29 -> 5
B30: 김동현 | F30: =SUM(C30:E30)+'3월'!J30 -> 8
B31: 김태호 | F31: =SUM(C31:E31)+'3월'!J31 -> 3
B32: 김혜연 | F32: =SUM(C32:E32)+'3월'!J32 -> 5
B33: 박민기 | C33: 1 | F33: =SUM(C33:E33)+'3월'!J33 -> 12
B34: 박상현 | F34: =SUM(C34:E34)+'3월'!J34 -> 9
B35: 방규현 | F35: =SUM(C35:E35)+'3월'!J35 -> 6
B36: 송예나 | F36: =SUM(C36:E36)+'3월'!J36 -> 5
B37: 심준보 | F37: =SUM(C37:E37)+'3월'!J37 -> 0
B38: 양정우 | E38: 1 | F38: =SUM(C38:E38)+'3월'!J38 -> 15
B39: 양지현 | F39: =SUM(C39:E39)+'3월'!J39 -> 0
B40: 유지현 | F40: =SUM(C40:E40)+'3월'!J40 -> 0
...

Sheet 3월
A1: 3월 | B1: 날짜 | C1: 03.01 | D1: 03.04 | E1: 03.09 | F1: 03.15 | G1: 03.23 | H1: 03.24 | I1: 03.30 | J1: 누적 점수
B2: 구분 | C2: 0차 정기모임 | D2: 비정기모임 | E2: 오리엔테이션 | F2: 1차 정기모임 | G2: 2차 정기모임 | H2: 비정기모임 | I2: 3차 정기모임
B3: 활동 | C3: 강남 | D3: 신촌 술 | E3: - | F3: 왕십리 보드게임 | G3: 합정 | H3: 신촌 정통집 | I3: 등산
B4: 주최자 | C4: - | D4: 이진진 | E4: - | F4: - | G4: - | H4: 이진진 | I4: -
A5: 운영진 | B5: 이원준 | D5: 1 | E5: 5 | F5: 3 | G5: 3 | H5: 1 | J5: =SUM(C5:I5) -> 13
B6: 이진진 | C6: 3 | D6: 2 | E6: 5 | H6: 2 | I6: 3 | J6: =SUM(C6:I6) -> 15
B7: 이예림 | C7: 1 | E7: 5 | I7: 1 | J7: =SUM(C7:I7) -> 7
B8: 신희찬 | C8: 3 | E8: 5 | J8: =SUM(C8:I8) -> 8
B9: 문제원 | C9: 3 | E9: 5 | I9: 3 | J9: =SUM(C9:I9) -> 11
B10: 유지훈 | C10: 3 | E10: 5 | G10: 3 | H10: 1 | I10: 3 | J10: =SUM(C10:I10) -> 15
B11: 이주연 | E11: 5 | J11: =SUM(C11:I11) -> 5
A12: 활동회원 | B12: 홍석범 | G12: 3 | J12: =SUM(C12:I12) -> 3
B13: 황인우 | C13: 1 | E13: 5 | J13: =SUM(C13:I13) -> 6
B14: 김해찬 | E14: 5 | J14: =SUM(C14:I14) -> 5
B15: 이규엽 | E15: 5 | G15: 3 | J15: =SUM(C15:I15) -> 8
B16: 하은희 | E16: 3 | J16: =SUM(C16:I16) -> 3
B17: 윤민식 | C17: 3 | E17: 3 | J17: =SUM(C17:I17) -> 6
B18: 이광민 | C18: 3 | E18: 5 | J18: =SUM(C18:I18) -> 8
B19: 이성현 | E19: 5 | J19: =SUM(C19:I19) -> 5
B20: 이수민 | D20: 1 | E20: 5 | I20: 1 | J20: =SUM(C20:I20) -> 7
B21: 이지원 | E21: 3 | J21: =SUM(C21:I21) -> 3
B22: 박소현 | E22: 3 | J22: =SUM(C22:I22) -> 3
B23: 양진석 | J23: =SUM(C23:I23) -> 0
B24: 홍채원 | C24: 3 | E24: 5 | J24: =SUM(C24:I24) -> 8
B25: 권지연 | C25: 3 | E25: 5 | J25: =SUM(C25:I25) -> 8
B26: 권희원 | J26: =SUM(C26:I26) -> 0
B27: 배규현 | J27: =SUM(C27:I27) -> 0
B28: 배환규 | C28: 3 | E28: 5 | G28: 3 | J28: =SUM(C28:I28) -> 11
B29: 안우석 | E29: 5 | J29: =SUM(C29:I29) -> 5
B30: 김동현 | E30: 5 | G30: 3 | J30: =SUM(C30:I30) -> 8
B31: 김태호 | C31: 3 | J31: =SUM(C31:I31) -> 3
B32: 김혜연 | E32: 5 | J32: =SUM(C32:I32) -> 5
B33: 박민기 | C33: 3 | D33: 1 | E33: 5 | H33: 1 | I33: 1 | J33: =SUM(C33:I33) -> 11
B34: 박상현 | C34: 3 | E34: 5 | H34: 1 | J34: =SUM(C34:I34) -> 9
B35: 방규현 | C35: 3 | F35: 3 | J35: =SUM(C35:I35) -> 6
B36: 송예나 | E36: 5 | J36: =SUM(C36:I36) -> 5
B37: 심준보 | J37: =SUM(C37:I37) -> 0
B38: 양정우 | C38: 3 | E38: 5 | F38: 3 | G38: 3 | J38: =SUM(C38:I38) -> 14
B39: 양지현 | J39: =SUM(C39:I39) -> 0
B40: 유지현 | J40: =SUM(C40:I40) -> 0
...
